<mujoco model="adam_lite">
	<compiler angle="radian" meshdir="assets" texturedir="assets"/>
	<default>
		<default class="adam_lite">
			<default class="visual">
				<geom material="sliver" type="mesh" contype="0" conaffinity="0" group="1" density="0" />
			</default>
			<default class="collision">
				<geom rgba="0 0 0 0" />
			</default>
			<geom solimp="0.95 0.95 0.001" solref="0.005 1"/> 
			<joint damping="0.001" armature="0.01" frictionloss="0.1"/>
		</default>
	</default>
	<asset>
		<material name="black" rgba="0.2 0.2 0.2 1" metallic="1" roughness="0" specular="1" shininess="1" />
		<material name="sliver" rgba="0.7 0.7 0.7 1" metallic="1" roughness="0" specular="1" shininess="1" />
		<texture name="pnd_torso" type="2d" file="logo.png" />
		<material name="pnd_logo" texture="pnd_torso" specular="1" shininess="1" />
		<mesh name="pelvis" file="pelvis_0.obj" />
		<mesh name="pelvis_1" file="pelvis_1.obj" />
		<mesh name="pelvis_2" file="pelvis_2.obj" />
		<mesh name="hipPitchLeft" file="hipPitchLeft_0.obj" />
		<mesh name="hipPitchLeft_1" file="hipPitchLeft_1.obj" />
		<mesh name="hipPitchLeft_2" file="hipPitchLeft_2.obj" />
		<mesh name="hipPitchLeft_3" file="hipPitchLeft_3.obj" />
		<mesh name="hipRollLeft" file="hipRollLeft_0.obj" />
		<mesh name="hipRollLeft_1" file="hipRollLeft_1.obj" />
		<mesh name="hipRollLeft_2" file="hipRollLeft_2.obj" />
		<mesh name="hipRollLeft_3" file="hipRollLeft_3.obj" />
		<mesh name="thighLeft" file="thighLeft_0.obj" />
		<mesh name="thighLeft_1" file="thighLeft_1.obj" />
		<mesh name="thighLeft_2" file="thighLeft_2.obj" />
		<mesh name="shinLeft" file="shinLeft_0.obj" />
		<mesh name="shinLeft_1" file="shinLeft_1.obj" />
		<mesh name="shinLeft_2" file="shinLeft_2.obj" />
		<mesh name="shinLeft_3" file="shinLeft_3.obj" />
		<mesh name="anklePitchLeft" file="anklePitchLeft.obj" />
		<mesh name="toeLeft" file="toeLeft_0.obj" />
		<mesh name="toeLeft_1" file="toeLeft_1.obj" />
		<mesh name="toeLeft_2" file="toeLeft_2.obj" />
		<mesh name="toeLeft_3" file="toeLeft_3.obj" />
		<mesh name="hipPitchRight" file="hipPitchRight_0.obj" />
		<mesh name="hipPitchRight_1" file="hipPitchRight_1.obj" />
		<mesh name="hipPitchRight_2" file="hipPitchRight_2.obj" />
		<mesh name="hipPitchRight_3" file="hipPitchRight_3.obj" />
		<mesh name="hipRollRight" file="hipRollRight_0.obj" />
		<mesh name="hipRollRight_1" file="hipRollRight_1.obj" />
		<mesh name="hipRollRight_2" file="hipRollRight_2.obj" />
		<mesh name="hipRollRight_3" file="hipRollRight_3.obj" />
		<mesh name="thighRight" file="thighRight_0.obj" />
		<mesh name="thighRight_1" file="thighRight_1.obj" />
		<mesh name="thighRight_2" file="thighRight_2.obj" />
		<mesh name="shinRight" file="shinRight_0.obj" />
		<mesh name="shinRight_1" file="shinRight_1.obj" />
		<mesh name="shinRight_2" file="shinRight_2.obj" />
		<mesh name="shinRight_3" file="shinRight_3.obj" />
		<mesh name="anklePitchRight" file="anklePitchRight.obj" />
		<mesh name="toeRight" file="toeRight_0.obj" />
		<mesh name="toeRight_1" file="toeRight_1.obj" />
		<mesh name="toeRight_2" file="toeRight_2.obj" />
		<mesh name="toeRight_3" file="toeRight_3.obj" />
		<mesh name="waistRoll" file="waistRoll_0.obj" />
		<mesh name="waistRoll_1" file="waistRoll_1.obj" />
		<mesh name="waistRoll_2" file="waistRoll_2.obj" />
		<mesh name="waistPitch" file="waistPitch_0.obj" />
		<mesh name="waistPitch_1" file="waistPitch_1.obj" />
		<mesh name="torso" file="torso_0.obj" />
		<mesh name="torso_1" file="torso_1.obj" />
		<mesh name="torso_2" file="torso_2.obj" />
		<mesh name="torso_3" file="torso_3.obj" />
		<mesh name="torso_4" file="torso_4.obj" />
		<mesh name="shoulderPitchLeft" file="shoulderPitchLeft.obj" />
		<mesh name="shoulderRollLeft" file="shoulderRollLeft_0.obj" />
		<mesh name="shoulderRollLeft_1" file="shoulderRollLeft_1.obj" />
		<mesh name="shoulderRollLeft_2" file="shoulderRollLeft_2.obj" />
		<mesh name="shoulderRollLeft_3" file="shoulderRollLeft_3.obj" />
		<mesh name="shoulderRollLeft_4" file="shoulderRollLeft_4.obj" />
		<mesh name="shoulderYawLeft" file="shoulderYawLeft_0.obj" />
		<mesh name="shoulderYawLeft_1" file="shoulderYawLeft_1.obj" />
		<mesh name="elbowLeft" file="elbowLeft_0.obj" />
		<mesh name="elbowLeft_1" file="elbowLeft_1.obj" />
		<mesh name="wristYawLeft" file="wristYawLeft_0_lite.obj" />
		<mesh name="wristYawLeft_1" file="wristYawLeft_1_lite.obj" />
		<mesh name="shoulderPitchRight" file="shoulderPitchRight.obj" />
		<mesh name="shoulderRollRight" file="shoulderRollRight_0.obj" />
		<mesh name="shoulderRollRight_1" file="shoulderRollRight_1.obj" />
		<mesh name="shoulderRollRight_2" file="shoulderRollRight_2.obj" />
		<mesh name="shoulderRollRight_3" file="shoulderRollRight_3.obj" />
		<mesh name="shoulderRollRight_4" file="shoulderRollRight_4.obj" />
		<mesh name="shoulderYawRight" file="shoulderYawRight_0.obj" />
		<mesh name="shoulderYawRight_1" file="shoulderYawRight_1.obj" />
		<mesh name="elbowRight" file="elbowRight_0.obj" />
		<mesh name="elbowRight_1" file="elbowRight_1.obj" />
		<mesh name="wristYawRight" file="wristYawRight_0_lite.obj" />
		<mesh name="wristYawRight_1" file="wristYawRight_1_lite.obj" />
	</asset>
	<worldbody>
		<body name="pelvis" pos="0 0 0.93">
			<inertial pos="-0.00034724 0.00000000 -0.00735759" quat="0.498488 0.49834 -0.501668 0.501493" mass="10.35646604" diaginertia="0.06211831 0.03451514 0.06877943" />
			<joint name="floating_joint" type="free" limited="false" actuatorfrclimited="false" />
			<geom mesh="pelvis" material="black" class="visual" />
			<geom mesh="pelvis_1" class="visual" />
			<geom mesh="pelvis_2" class="visual" />
			<geom size="0.1 0.1" quat="0.707388 0.706825 0 0" type="cylinder" class="collision" />
			<body name="hipPitchLeft" pos="0 0.096192 -0.033241" quat="0.953716 -0.300708 0 0">
				<inertial pos="-0.05660220 0.05761439 -0.00077159" quat="0.254193 0.376686 0.60653 0.652391" mass="2.23379987" diaginertia="0.00362189 0.00439139 0.00515496" />
				<joint name="hipPitch_Left" pos="0 0 0" axis="0 1 0" range="-2.164 2.164" actuatorfrcrange="-230 230" />
				<geom mesh="hipPitchLeft" material="pnd_logo" class="visual" />
				<geom mesh="hipPitchLeft_1" class="visual" />
				<geom mesh="hipPitchLeft_2" material="black" class="visual" />
				<geom mesh="hipPitchLeft_3" material="black" class="visual" />
				<body name="hipRollLeft" pos="-0.0255 0.069 0" quat="0.953716 0.300708 0 0">
					<inertial pos="0.03924162 0.00004107 -0.01032916" quat="-0.106213 0.535564 0.044112 0.836627" mass="1.35107789" diaginertia="0.00122242 0.00129116 0.00138754" />
					<joint name="hipRoll_Left" pos="0 0 0" axis="1 0 0" range="-0.733 1.605" actuatorfrcrange="-160 160" />
					<geom mesh="hipRollLeft" class="visual" />
					<geom mesh="hipRollLeft_1" material="black" class="visual" />
					<geom mesh="hipRollLeft_2" material="black" class="visual" />
					<geom mesh="hipRollLeft_3" material="pnd_logo" class="visual" />
					<body name="thighLeft" pos="0.044 0 -0.0525">
						<inertial pos="0.00244052 -0.00866423 -0.13433631" quat="0.675183 0.0507397 -0.0286771 0.735344" mass="6.43432838" diaginertia="0.05827182 0.06333936 0.01331159" />
						<joint name="hipYaw_Left" pos="0 0 0" axis="0 0 1" range="-0.785 0.785" actuatorfrcrange="-105 105" />
						<geom mesh="thighLeft" material="pnd_logo" class="visual" />
						<geom mesh="thighLeft_1" class="visual" />
						<geom mesh="thighLeft_2" material="black" class="visual" />
						<geom size="0.09 0.068 0.15" quat="0.9990482 -0.0436194 0 0" pos="0 -0.01 -0.13" type="ellipsoid" class="collision" />
						<body name="shinLeft" pos="0 -0.0355 -0.369">
							<inertial pos="-0.00080913 0.00097265 -0.145408" quat="0.6612 -0.003018 -0.00584383 0.75018" mass="2.25363003" diaginertia="0.02151350 0.02158746 0.00136992" />
							<joint name="kneePitch_Left" pos="0 0 0" axis="0 1 0" range="0.052 2.391" actuatorfrcrange="-230 230" />
							<geom mesh="shinLeft" class="visual" />
							<geom mesh="shinLeft_1" material="black" class="visual" />
							<geom mesh="shinLeft_2" material="pnd_logo" class="visual" />
							<geom mesh="shinLeft_3" material="black" class="visual" />
							<geom size="0.04 0.03 0.15" pos="0 0 -0.2" type="box" class="collision" />
							<body name="anklePitchLeft" pos="0 0 -0.37">
								<inertial pos="0 0 0" mass="0.03014230" diaginertia="3.23e-06 3.23e-06 2.1e-06" />
								<joint name="anklePitch_Left" pos="0 0 0" axis="0 1 0" range="-1.0 0.35" actuatorfrcrange="-40 40" armature="0.001" />
								<geom mesh="anklePitchLeft" class="visual" />
								<body name="toeLeft">
									<inertial pos="0.0370066 -2.063e-05 -0.0419868" quat="0.00469469 0.673963 -0.00294814 0.738744" mass="0.63479601" diaginertia="0.00159292 0.00152195 0.000273726" />
									<joint name="ankleRoll_Left" pos="0 0 0" axis="1 0 0" range="-0.3491 0.3491" actuatorfrcrange="-12 12" />
									<geom mesh="toeLeft" material="pnd_logo" class="visual" />
									<geom mesh="toeLeft_1" class="visual" />
									<geom mesh="toeLeft_2" material="pnd_logo" class="visual" />
									<geom mesh="toeLeft_3" class="visual" />
									<geom name="toe1_left" size="0.12 0.05 0.015" pos="0.047 0.0 -0.05" quat="0 0 0 1" type="box" class="collision" />
								</body>
							</body>
						</body>
					</body>
				</body>
			</body>
			<body name="hipPitchRight" pos="0 -0.096192 -0.033241" quat="0.953716 0.300708 0 0">
				<inertial pos="-0.0581816 -0.0588696 -0.00032981" quat="0.648631 0.611936 0.367995 0.263425" mass="2.23477271" diaginertia="0.00362315 0.00439419 0.00515804" />
				<joint name="hipPitch_Right" pos="0 0 0" axis="0 1 0" range="-2.164 2.164" actuatorfrcrange="-230 230" />
				<geom mesh="hipPitchRight" material="pnd_logo" class="visual" />
				<geom mesh="hipPitchRight_1" class="visual" />
				<geom mesh="hipPitchRight_2" material="black" class="visual" />
				<geom mesh="hipPitchRight_3" material="black" class="visual" />
				<body name="hipRollRight" pos="-0.0255 -0.069 0" quat="0.953716 -0.300708 0 0">
					<inertial pos="0.0398817 0.00011594 -0.0110209" quat="0.102657 0.530738 -0.0414919 0.840272" mass="1.35169943" diaginertia="0.00122275 0.00129208 0.00138861" />
					<joint name="hipRoll_Right" pos="0 0 0" axis="1 0 0" range="-1.605 0.733" actuatorfrcrange="-160 160" />
					<geom mesh="hipRollRight" material="black" class="visual" />
					<geom mesh="hipRollRight_1" material="black" class="visual" />
					<geom mesh="hipRollRight_2" material="sliver" class="visual" />
					<geom mesh="hipRollRight_3" material="black" class="visual" />
					<body name="thighRight" pos="0.044 0 -0.0525">
						<inertial pos="0.00332701 0.0111027 -0.13529" quat="0.734268 -0.0285841 0.0502267 0.676395" mass="6.43084152" diaginertia="0.05823192 0.06331326 0.01331917" />
						<joint name="hipYaw_Right" pos="0 0 0" axis="0 0 1" range="-0.785 0.785" actuatorfrcrange="-105 105" />
						<geom mesh="thighRight" material="pnd_logo" class="visual" />
						<geom mesh="thighRight_1" class="visual" />
						<geom mesh="thighRight_2" material="black" class="visual" />
						<geom size="0.09 0.068 0.15" quat="0.9990482 0.0436194 0 0" pos="0 0.01 -0.13" type="ellipsoid" class="collision" />
						<body name="shinRight" pos="0 0.0355 -0.369">
							<inertial pos="-0.00079979 -0.00097288 -0.146351" quat="0.750551 -0.00574198 -0.00281104 0.660781" mass="2.25459286" diaginertia="0.02149493 0.02156785 0.00137005" />
							<joint name="kneePitch_Right" pos="0 0 0" axis="0 1 0" range="0.052 2.391" actuatorfrcrange="-230 230" />
							<geom mesh="shinRight" material="pnd_logo" class="visual" />
							<geom mesh="shinRight_1" class="visual" />
							<geom mesh="shinRight_2" material="black" class="visual" />
							<geom mesh="shinRight_3" material="black" class="visual" />
							<geom size="0.04 0.03 0.15" pos="0 0 -0.2" type="box" class="collision" />
							<body name="anklePitchRight" pos="0 0 -0.37">
								<inertial pos="0 0 0" mass="0.03014230" diaginertia="3.23e-06 3.23e-06 2.1e-06" />
								<joint name="anklePitch_Right" pos="0 0 0" axis="0 1 0" range="-1.0 0.35" actuatorfrcrange="-40 40" armature="0.001" />
								<geom mesh="anklePitchRight" class="visual" />
								<body name="toeRight">
									<inertial pos="0.037003 2.151e-05 -0.0419756" quat="-0.00470409 0.67392 0.00290833 0.738784" mass="0.63480789" diaginertia="0.00159272 0.00152205 0.000274003" />
									<joint name="ankleRoll_Right" pos="0 0 0" axis="1 0 0" range="-0.3491 0.3491" actuatorfrcrange="-12 12" />
									<geom mesh="toeRight" material="pnd_logo" class="visual" />
									<geom mesh="toeRight_1" material="pnd_logo" class="visual" />
									<geom mesh="toeRight_2" class="visual" />
									<geom mesh="toeRight_3" material="pnd_logo" class="visual" />
									<geom name="toe_right" size="0.12 0.05 0.015" pos="0.047 0.0 -0.05" quat="0 0 0 1" type="box" class="collision" />
								</body>
							</body>
						</body>
					</body>
				</body>
			</body>
			<body name="waistRoll" pos="0 0 0.044">
				<inertial pos="0.00212014 0.00212051 0.0399999" quat="0.923038 0.0138501 0.0334997 -0.382998" mass="2.36268465" diaginertia="0.00543041 0.00543044 0.00184993" />
				<joint name="waistRoll" pos="0 0 0" axis="1 0 0" range="-0.226 0.226" actuatorfrcrange="-110 110" />
				<geom mesh="waistRoll" material="black" class="visual" />
				<geom mesh="waistRoll_1" class="visual" />
				<geom mesh="waistRoll_2" class="visual" />
				<body name="waistPitch" pos="0 0 0.08">
					<inertial pos="-0.00066627 0.00070478 0.0250655" quat="0.490275 0.505791 -0.509543 0.494137" mass="0.56353776" diaginertia="0.00151470 0.00067279 0.00155907" />
					<joint name="waistPitch" pos="0 0 0" axis="0 1 0" range="-0.785 1.308" actuatorfrcrange="-110 110" />
					<geom mesh="waistPitch" material="black" class="visual" />
					<geom mesh="waistPitch_1" class="visual" />
					<body name="torso" pos="0 0.0005 0.053">
						<inertial pos="0.00080019 -3.149e-05 0.183003" quat="0.999892 -0.000596029 -0.0147105 0.000333188" mass="12.89652496" diaginertia="0.19855642 0.16612827 0.06625123" />
						<joint name="waistYaw" pos="0 0 0" axis="0 0 1" range="-0.78 0.78" actuatorfrcrange="-110 110" />
						<geom mesh="torso" material="pnd_logo" class="visual" />
						<geom mesh="torso_1" material="pnd_logo" class="visual" />
						<geom mesh="torso_2" class="visual" />
						<geom mesh="torso_3" class="visual" />
						<geom mesh="torso_4" material="black" class="visual" />
						<geom size="0.13" pos="0 0 0.15" class="collision" />
						<body name="shoulderPitchLeft" pos="0 0.16011 0.25742" quat="0.984807 0.17365 0 0">
							<inertial pos="-0.00150404 0.0268884 0.00010848" quat="-0.0108407 0.705644 0.0165332 0.70829" mass="0.20310000" diaginertia="0.00017020 0.00028895 0.00034385" />
							<joint name="shoulderPitch_Left" pos="0 0 0" axis="0 1 0" range="-3.560 1.989" actuatorfrcrange="-65 65" />
							<geom mesh="shoulderPitchLeft" class="visual" />
							<body name="shoulderRollLeft" pos="0.0335 0.0435 0" quat="0.984807 -0.17365 0 0">
								<inertial pos="-0.0286045 0.0110425 -0.0140531" quat="0.376737 -0.1477 0.30048 0.863693" mass="0.72480000" diaginertia="0.00090812 0.00071197 0.00060954" />
								<joint name="shoulderRoll_Left" pos="0 0 0" axis="1 0 0" range="-0.575 2.74" actuatorfrcrange="-65 65" />
								<geom mesh="shoulderRollLeft" class="visual" />
								<geom mesh="shoulderRollLeft_1" class="visual" />
								<geom mesh="shoulderRollLeft_2" material="black" class="visual" />
								<geom mesh="shoulderRollLeft_3" class="visual" />
								<geom mesh="shoulderRollLeft_4" class="visual" />
								<geom size="0.035 0.05" pos="-0.03 0 0" quat="0.707105 0 0.707108 0" type="cylinder" class="collision" />
								<body name="shoulderYawLeft" pos="-0.0335 0.034 -0.0585">
									<inertial pos="-0.00069813 0.00102049 -0.0684231" quat="0.999758 -0.0173498 -0.010067 -0.00907623" mass="0.69630000" diaginertia="0.00317887 0.00310433 0.00039452" />
									<joint name="shoulderYaw_Left" pos="0 0 0" axis="0 0 1" range="-2.53 2.53" actuatorfrcrange="-65 65" />
									<geom mesh="shoulderYawLeft" class="visual" />
									<geom mesh="shoulderYawLeft" material="black" class="visual" />
									<geom size="0.038 0.075" pos="0 0 -0.08" type="cylinder" class="collision" />
									<body name="elbowLeft" pos="0 -0.0285 -0.20415">
										<inertial pos="-0.0216442 0.0277621 -0.0446964" quat="0.897923 0.0631943 -0.210786 -0.381195" mass="0.85400000" diaginertia="0.00072987 0.00080410 0.00047565" />
										<joint name="elbow_Left" pos="0 0 0" axis="0 1 0" range="-2.443 0.174" actuatorfrcrange="-30 30" />
										<geom mesh="elbowLeft" class="visual" />
										<geom mesh="elbowLeft_1" class="visual" />
										<body name="wristYawLeft" pos="-0.025 0.0285 -0.0729">
											<inertial pos="1.826e-05 -0.00013856 -0.156089" quat="0.724287 0.000597867 -0.000753285 0.689498" mass="0.73460000" diaginertia="0.00772306 0.00772311 0.00029992" />
											<geom mesh="wristYawLeft" material="black" class="visual" />
											<geom mesh="wristYawLeft_1" class="visual" />
										</body>
									</body>
								</body>
							</body>
						</body>
						<body name="shoulderPitchRight" pos="0 -0.16011 0.25742" quat="0.984807 -0.17365 0 0">
							<inertial pos="-0.00150404 -0.0268723 0.00010766" quat="0.0103482 0.705652 -0.0161722 0.708298" mass="0.20310000" diaginertia="0.00017009 0.00028895 0.00034374" />
							<joint name="shoulderPitch_Right" pos="0 0 0" axis="0 1 0" range="-3.560 1.989" actuatorfrcrange="-65 65" />
							<geom mesh="shoulderPitchRight" class="visual" />
							<body name="shoulderRollRight" pos="0.0335 -0.0435 0" quat="0.984807 0.17365 0 0">
								<inertial pos="-0.0286045 -0.0110459 -0.0140499" quat="0.863671 0.30066 -0.147632 0.37667" mass="0.72480000" diaginertia="0.00090814 0.00071184 0.00060969" />
								<joint name="shoulderRoll_Right" pos="0 0 0" axis="1 0 0" range="-2.74 0.575" actuatorfrcrange="-65 65" />
								<geom mesh="shoulderRollRight" class="visual" />
								<geom mesh="shoulderRollRight_1" material="black" class="visual" />
								<geom mesh="shoulderRollRight_2" class="visual" />
								<geom mesh="shoulderRollRight_3" class="visual" />
								<geom mesh="shoulderRollRight_4" class="visual" />
								<geom size="0.035 0.05" pos="-0.03 0 0" quat="0.707105 0 0.707108 0" type="cylinder" class="collision" />
								<body name="shoulderYawRight" pos="-0.0335 -0.034 -0.0585">
									<inertial pos="-0.00089274 -0.00096643 -0.0698052" quat="0.999767 0.0172729 -0.0100354 0.00814411" mass="0.69630000" diaginertia="0.00304636 0.00297764 0.00041751" />
									<joint name="shoulderYaw_Right" pos="0 0 0" axis="0 0 1" range="-2.530 2.530" actuatorfrcrange="-65 65" />
									<geom mesh="shoulderYawRight" material="black" class="visual" />
									<geom mesh="shoulderYawRight_1" class="visual" />
									<geom size="0.038 0.075" pos="0 0 -0.08" type="cylinder" class="collision" />
									<body name="elbowRight" pos="0 0.0285 -0.20415">
										<inertial pos="-0.0121233 -0.0262957 -0.026584" quat="0.913189 -0.0537938 -0.213066 0.343213" mass="0.85400000" diaginertia="0.00099546 0.00111379 0.00053993" />
										<joint name="elbow_Right" pos="0 0 0" axis="0 1 0" range="-2.443 0.174" actuatorfrcrange="-30 30" />
										<geom mesh="elbowRight" class="visual" />
										<geom mesh="elbowRight_1" class="visual" />
										<body name="wristYawRight" pos="-0.025 -0.0285 -0.0729">
											<inertial pos="1.64e-05 0.00018166 -0.177952" quat="0.698472 -0.000816832 0.000645819 0.715636" mass="0.73460000" diaginertia="0.00788006 0.00787989 0.000312547" />
											<geom mesh="wristYawRight" material="black" class="visual" />
											<geom mesh="wristYawRight_1" class="visual" />
										</body>
									</body>
								</body>
							</body>
						</body>
					</body>
				</body>
			</body>
			<site name="imu" pos="0 0 0" />
		</body>
	</worldbody>
	<actuator>
		<motor name="hipPitch_Left" joint="hipPitch_Left" />
		<motor name="hipRoll_Left" joint="hipRoll_Left" />
		<motor name="hipYaw_Left" joint="hipYaw_Left" />
		<motor name="kneePitch_Left" joint="kneePitch_Left" />
		<motor name="anklePitch_Left" joint="anklePitch_Left" />
		<motor name="ankleRoll_Left" joint="ankleRoll_Left" />
		<motor name="hipPitch_Right" joint="hipPitch_Right" />
		<motor name="hipRoll_Right" joint="hipRoll_Right" />
		<motor name="hipYaw_Right" joint="hipYaw_Right" />
		<motor name="kneePitch_Right" joint="kneePitch_Right" />
		<motor name="anklePitch_Right" joint="anklePitch_Right" />
		<motor name="ankleRoll_Right" joint="ankleRoll_Right" />
		<motor name="waistRoll" joint="waistRoll" />
		<motor name="waistPitch" joint="waistPitch" />
		<motor name="waistYaw" joint="waistYaw" />
		<motor name="shoulderPitch_Left" joint="shoulderPitch_Left" />
		<motor name="shoulderRoll_Left" joint="shoulderRoll_Left" />
		<motor name="shoulderYaw_Left" joint="shoulderYaw_Left" />
		<motor name="elbow_Left" joint="elbow_Left" />
		<motor name="shoulderPitch_Right" joint="shoulderPitch_Right" />
		<motor name="shoulderRoll_Right" joint="shoulderRoll_Right" />
		<motor name="shoulderYaw_Right" joint="shoulderYaw_Right" />
		<motor name="elbow_Right" joint="elbow_Right" />
	</actuator>
	<!-- <sensor>
		<accelerometer name="BodyAcc" site="imu" />
		<gyro name="BodyGyro" site="imu" />
	</sensor> -->
    
	
	<statistic center="0 0 1" extent="1.8" />
	<visual>
		<headlight diffuse="0.6 0.6 0.6" ambient="0.3 0.3 0.3" specular="0 0 0" />
		<rgba haze="0.15 0.25 0.35 1" />
		<global azimuth="160" elevation="-20" />
	</visual>
	<asset>
		<texture type="skybox" builtin="gradient" rgb1="0.3 0.5 0.7" rgb2="0 0 0" width="512" height="3072" />
		<texture type="2d" name="groundplane" builtin="checker" mark="edge" rgb1="0.2 0.3 0.4" rgb2="0.1 0.2 0.3" markrgb="0.8 0.8 0.8" width="300" height="300" />
		<material name="groundplane" texture="groundplane" texuniform="true" texrepeat="5 5" reflectance="0.2" />
	</asset>
	<worldbody>
		<light pos="0 0 3.5" dir="0 0 -1" directional="true" />
		<geom name="floor" size="0 0 0.05" type="plane" material="groundplane" />
	</worldbody>

</mujoco>
