<mujoco model="standard_inspireHands2">
	<compiler angle="radian" meshdir="assets" texturedir="assets" />
	<default>
		<default class="adam_lite">
			<default class="visual">
				<geom material="sliver" type="mesh" contype="0" conaffinity="0" group="1" density="0" />
			</default>
			<default class="collision">
				<geom rgba="1 0 0 0" />
			</default>
		</default>
	</default>
	<asset>
		<material name="black" rgba="0.2 0.2 0.2 1" metallic="1" roughness="0" specular="1" shininess="1" />
		<material name="sliver" rgba="0.7 0.7 0.7 1" metallic="1" roughness="0" specular="1" shininess="1" />
		<texture name="pnd_torso" type="2d" file="logo.png" />
		<material name="pnd_logo" texture="pnd_torso" specular="1" shininess="1" />
		<mesh name="pelvis" file="pelvis_0.obj" />
		<mesh name="hipPitchLeft" file="hipPitchLeft_0.obj" />
		<mesh name="hipRollLeft" file="hipRollLeft_0.obj" />
		<mesh name="thighLeft" file="thighLeft_0.obj" />
		<mesh name="shinLeft" file="shinLeft_0.obj" />
		<mesh name="anklePitchLeft" file="anklePitchLeft.obj" />
		<mesh name="toeLeft" file="toeLeft_0.obj" />
		<mesh name="hipPitchRight" file="hipPitchRight_0.obj" />
		<mesh name="hipRollRight" file="hipRollRight_0.obj" />
		<mesh name="thighRight" file="thighRight_0.obj" />
		<mesh name="shinRight" file="shinRight_0.obj" />
		<mesh name="anklePitchRight" file="anklePitchRight.obj" />
		<mesh name="toeRight" file="toeRight_0.obj" />
		<mesh name="waistRoll" file="waistRoll_0.obj" />
		<mesh name="waistPitch" file="waistPitch_0.obj" />
		<mesh name="torso" file="torso_0.obj" />
		<mesh name="shoulderPitchLeft" file="shoulderPitchLeft.obj" />
		<mesh name="shoulderRollLeft" file="shoulderRollLeft_0.obj" />
		<mesh name="shoulderYawLeft" file="shoulderYawLeft_0.obj" />
		<mesh name="elbowLeft" file="elbowLeft_0.obj" />
		<mesh name="shoulderPitchRight" file="shoulderPitchRight.obj" />
		<mesh name="shoulderRollRight" file="shoulderRollRight_0.obj" />
		<mesh name="shoulderYawRight" file="shoulderYawRight_0.obj" />
		<mesh name="elbowRight" file="elbowRight_0.obj" />
	</asset>
	<worldbody>
		<body name="pelvis" pos="0 0 0.95">
			<inertial pos="-0.00120269 -1.18988e-06 -0.00802076" quat="0.498488 0.49834 -0.501669 0.501494" mass="10.1883" diaginertia="0.0752974 0.0684951 0.0376324" />
			<joint name="floating_joint" type="free" limited="false" actuatorfrclimited="false" />
			<geom mesh="pelvis" material="black" class="visual" />
			<geom mesh="pelvis" class="visual" />
			<geom mesh="pelvis" class="visual" />
			<geom size="0.11 0.03" quat="0.707388 0.706825 0 0" type="capsule" class="collision" />
			<body name="hipPitchLeft" pos="0 0.096192 -0.033241" quat="0.953716 -0.300708 0 0">
				<inertial pos="-0.0581819 0.0588948 -0.00031205" quat="0.254193 0.376686 0.60653 0.652391" mass="2.15125" diaginertia="0.00511936 0.00508028 0.00314942" />
				<joint name="hipPitch_Left" pos="0 0 0" axis="0 1 0" range="-2.164 2.164" actuatorfrcrange="-230 230" />
				<geom mesh="hipPitchLeft" material="pnd_logo" class="visual" />
				<geom mesh="hipPitchLeft" class="visual" />
				<geom mesh="hipPitchLeft" material="black" class="visual" />
				<geom mesh="hipPitchLeft" material="black" class="visual" />
				<body name="hipRollLeft" pos="-0.0255 0.069 0" quat="0.953716 0.300708 0 0">
					<inertial pos="0.0399541 -0.00011618 -0.011021" quat="-0.106213 0.535564 0.044112 0.836627" mass="1.29422" diaginertia="0.001475 0.001371 0.00131215" />
					<joint name="hipRoll_Left" pos="0 0 0" axis="1 0 0" range="-0.733 1.605" actuatorfrcrange="-160 160" />
					<geom mesh="hipRollLeft" class="visual" />
					<geom mesh="hipRollLeft" material="black" class="visual" />
					<geom mesh="hipRollLeft" material="black" class="visual" />
					<geom mesh="hipRollLeft" material="pnd_logo" class="visual" />
					<body name="thighLeft" pos="0.044 0 -0.0525">
						<inertial pos="0.00331195 -0.0111247 -0.135198" quat="0.675183 0.0507397 -0.0286771 0.735344" mass="6.6475" diaginertia="0.0628071 0.056896 0.0145546" />
						<joint name="hipYaw_Left" pos="0 0 0" axis="0 0 1" range="-0.785 0.785" actuatorfrcrange="-105 105" />
						<geom mesh="thighLeft" material="pnd_logo" class="visual" />
						<geom mesh="thighLeft" class="visual" />
						<geom mesh="thighLeft" material="black" class="visual" />
						<geom size="0.09 0.068 0.15" quat="0.9990482 -0.0436194 0 0" pos="0 -0.01 -0.13" type="ellipsoid" class="collision" />
						<body name="shinLeft" pos="0 -0.0355 -0.369">
							<inertial pos="-0.00080913 0.00097265 -0.145408" quat="0.6612 -0.003018 -0.00584383 0.75018" mass="2.19866" diaginertia="0.0194116 0.0193296 0.00136517" />
							<joint name="kneePitch_Left" pos="0 0 0" axis="0 1 0" range="0.052 2.391" actuatorfrcrange="-230 230" />
							<geom mesh="shinLeft" class="visual" />
							<geom mesh="shinLeft" material="black" class="visual" />
							<geom mesh="shinLeft" material="pnd_logo" class="visual" />
							<geom mesh="shinLeft" material="black" class="visual" />
							<geom size="0.04 0.11" pos="0 0 -0.2" type="capsule" class="collision" />
							<body name="anklePitchLeft" pos="0 0 -0.37">
								<inertial pos="0 0 0" mass="0.031" diaginertia="3.23e-06 3.23e-06 2.1e-06" />
								<joint name="anklePitch_Left" pos="0 0 0" axis="0 1 0" range="-1.0 0.35" actuatorfrcrange="-40 40" armature="0.001" />
								<geom mesh="anklePitchLeft" class="visual" />
								<body name="toeLeft">
									<inertial pos="0.0370066 -2.063e-05 -0.0419868" quat="0.00469469 0.673963 -0.00294814 0.738744" mass="0.4758" diaginertia="0.00159292 0.00152195 0.000273726" />
									<joint name="ankleRoll_Left" pos="0 0 0" axis="1 0 0" range="-0.3491 0.3491" actuatorfrcrange="-12 12" />
									<geom mesh="toeLeft" material="pnd_logo" class="visual" />
									<geom mesh="toeLeft" class="visual" />
									<geom mesh="toeLeft" material="pnd_logo" class="visual" />
									<geom mesh="toeLeft" class="visual" />
									<geom name="toe1_left" size="0.12 0.05 0.015" pos="0.047 0.0 -0.05" quat="0 0 0 1" type="box" class="collision" />
								</body>
							</body>
						</body>
					</body>
				</body>
			</body>
			<body name="hipPitchRight" pos="0 -0.096192 -0.033241" quat="0.953716 0.300708 0 0">
				<inertial pos="-0.0581816 -0.0588696 -0.00032981" quat="0.648631 0.611936 0.367995 0.263425" mass="2.15124" diaginertia="0.0051141 0.0050828 0.00314994" />
				<joint name="hipPitch_Right" pos="0 0 0" axis="0 1 0" range="-2.164 2.164" actuatorfrcrange="-230 230" />
				<geom mesh="hipPitchRight" material="pnd_logo" class="visual" />
				<geom mesh="hipPitchRight" class="visual" />
				<geom mesh="hipPitchRight" material="black" class="visual" />
				<geom mesh="hipPitchRight" material="black" class="visual" />
				<body name="hipRollRight" pos="-0.0255 -0.069 0" quat="0.953716 -0.300708 0 0">
					<inertial pos="0.0398817 0.00011594 -0.0110209" quat="0.102657 0.530738 -0.0414919 0.840272" mass="1.29423" diaginertia="0.00147637 0.00137013 0.00131019" />
					<joint name="hipRoll_Right" pos="0 0 0" axis="1 0 0" range="-1.605 0.733" actuatorfrcrange="-160 160" />
					<geom mesh="hipRollRight" material="black" class="visual" />
					<geom mesh="hipRollRight" material="black" class="visual" />
					<geom mesh="hipRollRight" material="sliver" class="visual" />
					<geom mesh="hipRollRight" material="black" class="visual" />
					<body name="thighRight" pos="0.044 0 -0.0525">
						<inertial pos="0.00332701 0.0111027 -0.13529" quat="0.734268 -0.0285841 0.0502267 0.676395" mass="6.64755" diaginertia="0.0630598 0.0571586 0.0145332" />
						<joint name="hipYaw_Right" pos="0 0 0" axis="0 0 1" range="-0.785 0.785" actuatorfrcrange="-105 105" />
						<geom mesh="thighRight" material="pnd_logo" class="visual" />
						<geom mesh="thighRight" class="visual" />
						<geom mesh="thighRight" material="black" class="visual" />
						<geom size="0.09 0.068 0.15" quat="0.9990482 0.0436194 0 0" pos="0 0.01 -0.13" type="ellipsoid" class="collision" />
						<body name="shinRight" pos="0 0.0355 -0.369">
							<inertial pos="-0.00079979 -0.00097288 -0.146351" quat="0.750551 -0.00574198 -0.00281104 0.660781" mass="2.20809" diaginertia="0.0198783 0.0197996 0.00136891" />
							<joint name="kneePitch_Right" pos="0 0 0" axis="0 1 0" range="0.052 2.391" actuatorfrcrange="-230 230" />
							<geom mesh="shinRight" material="pnd_logo" class="visual" />
							<geom mesh="shinRight" class="visual" />
							<geom mesh="shinRight" material="black" class="visual" />
							<geom mesh="shinRight" material="black" class="visual" />
							<geom size="0.04 0.11" pos="0 0 -0.2" type="capsule" class="collision" />
							<body name="anklePitchRight" pos="0 0 -0.37">
								<inertial pos="0 0 0" mass="0.031" diaginertia="3.23e-06 3.23e-06 2.1e-06" />
								<joint name="anklePitch_Right" pos="0 0 0" axis="0 1 0" range="-1.0 0.35" actuatorfrcrange="-40 40" armature="0.001" />
								<geom mesh="anklePitchRight" class="visual" />
								<body name="toeRight">
									<inertial pos="0.037003 2.151e-05 -0.0419756" quat="-0.00470409 0.67392 0.00290833 0.738784" mass="0.4758" diaginertia="0.00159272 0.00152205 0.000274003" />
									<joint name="ankleRoll_Right" pos="0 0 0" axis="1 0 0" range="-0.3491 0.3491" actuatorfrcrange="-12 12" />
									<geom mesh="toeRight" material="pnd_logo" class="visual" />
									<geom mesh="toeRight" material="pnd_logo" class="visual" />
									<geom mesh="toeRight" class="visual" />
									<geom mesh="toeRight" material="pnd_logo" class="visual" />
									<geom name="toe_right" size="0.12 0.05 0.015" pos="0.047 0.0 -0.05" quat="0 0 0 1" type="box" class="collision" />
								</body>
							</body>
						</body>
					</body>
				</body>
			</body>
			<body name="waistRoll" pos="0 0 0.044">
				<inertial pos="0.00212014 0.00212051 0.0399999" quat="0.923038 0.0138501 0.0334997 -0.382998" mass="2.18431" diaginertia="0.0049266 0.00489447 0.00200283" />
				<joint name="waistRoll" pos="0 0 0" axis="1 0 0" range="-0.226 0.226" actuatorfrcrange="-110 110" />
				<geom mesh="waistRoll" material="black" class="visual" />
				<geom mesh="waistRoll" class="visual" />
				<geom mesh="waistRoll" class="visual" />
				<body name="waistPitch" pos="0 0 0.08">
					<inertial pos="-0.00066627 0.00070478 0.0250655" quat="0.490275 0.505791 -0.509543 0.494137" mass="0.4987" diaginertia="0.00144147 0.0013606 0.000609845" />
					<joint name="waistPitch" pos="0 0 0" axis="0 1 0" range="-0.785 1.308" actuatorfrcrange="-110 110" />
					<geom mesh="waistPitch" material="black" class="visual" />
					<geom mesh="waistPitch" class="visual" />
					<body name="torso" pos="0 0.0005 0.053">
						<inertial pos="0.00080019 -3.149e-05 0.183003" quat="0.999892 -0.000596029 -0.0147105 0.000333188" mass="13.286" diaginertia="0.199038 0.161154 0.0724599" />
						<joint name="waistYaw" pos="0 0 0" axis="0 0 1" range="-0.78 0.78" actuatorfrcrange="-110 110" />
						<geom mesh="torso" material="pnd_logo" class="visual" />
						<geom mesh="torso" material="pnd_logo" class="visual" />
						<geom mesh="torso" class="visual" />
						<geom mesh="torso" class="visual" />
						<geom mesh="torso" material="black" class="visual" />
						<geom size="0.13" pos="0 0 0.15" class="collision" />
						<body name="shoulderPitchLeft" pos="0 0.16011 0.25742" quat="0.984807 0.17365 0 0">
							<inertial pos="-0.00150404 0.0268884 0.00010848" quat="-0.0108407 0.705644 0.0165332 0.70829" mass="0.2031" diaginertia="0.000343856 0.000289125 0.000170019" />
							<joint name="shoulderPitch_Left" pos="0 0 0" axis="0 1 0" range="-3.560 1.989" actuatorfrcrange="-65 65" />
							<geom mesh="shoulderPitchLeft" class="visual" />
							<body name="shoulderRollLeft" pos="0.0335 0.0435 0" quat="0.984807 -0.17365 0 0">
								<inertial pos="-0.0286045 0.0110425 -0.0140531" quat="0.376737 -0.1477 0.30048 0.863693" mass="0.7248" diaginertia="0.000958643 0.000867101 0.000403886" />
								<joint name="shoulderRoll_Left" pos="0 0 0" axis="1 0 0" range="-0.575 2.74" actuatorfrcrange="-65 65" />
								<geom mesh="shoulderRollLeft" class="visual" />
								<geom mesh="shoulderRollLeft" class="visual" />
								<geom mesh="shoulderRollLeft" material="black" class="visual" />
								<geom mesh="shoulderRollLeft" class="visual" />
								<geom mesh="shoulderRollLeft" class="visual" />
								<geom size="0.0354 0.021" pos="-0.035 0 0" quat="0.707105 0 0.707108 0" type="capsule" class="collision" />
								<body name="shoulderYawLeft" pos="-0.0335 0.034 -0.0585">
									<inertial pos="-0.00069813 0.00102049 -0.0684231" quat="0.999758 -0.0173498 -0.010067 -0.00907623" mass="0.6963" diaginertia="0.00317999 0.00310761 0.000390118" />
									<joint name="shoulderYaw_Left" pos="0 0 0" axis="0 0 1" range="-2.53 2.53" actuatorfrcrange="-65 65" />
									<geom mesh="shoulderYawLeft" class="visual" />
									<geom mesh="shoulderYawLeft" material="black" class="visual" />
									<geom size="0.0302 0.06" pos="0 0 -0.08" type="capsule" class="collision" />
									<body name="elbowLeft" pos="0 -0.0285 -0.20415">
										<inertial pos="-0.0216442 0.0277621 -0.0446964" quat="0.897923 0.0631943 -0.210786 -0.381195" mass="0.854" diaginertia="0.000828975 0.000780354 0.000400291" />
										<joint name="elbow_Left" pos="0 0 0" axis="0 1 0" range="-2.443 0.174" actuatorfrcrange="-30 30" />
										<geom mesh="elbowLeft" class="visual" />
										<geom mesh="elbowLeft" class="visual" />

									</body>
								</body>
							</body>
						</body>
						<body name="shoulderPitchRight" pos="0 -0.16011 0.25742" quat="0.984807 -0.17365 0 0">
							<inertial pos="-0.00150404 -0.0268723 0.00010766" quat="0.0103482 0.705652 -0.0161722 0.708298" mass="0.2031" diaginertia="0.000343746 0.000289114 0.00016992" />
							<joint name="shoulderPitch_Right" pos="0 0 0" axis="0 1 0" range="-3.560 1.989" actuatorfrcrange="-65 65" />
							<geom mesh="shoulderPitchRight" class="visual" />
							<body name="shoulderRollRight" pos="0.0335 -0.0435 0" quat="0.984807 0.17365 0 0">
								<inertial pos="-0.0286045 -0.0110459 -0.0140499" quat="0.863671 0.30066 -0.147632 0.37667" mass="0.7248" diaginertia="0.000958654 0.000867086 0.00040393" />
								<joint name="shoulderRoll_Right" pos="0 0 0" axis="1 0 0" range="-2.74 0.575" actuatorfrcrange="-65 65" />
								<geom mesh="shoulderRollRight" class="visual" />
								<geom mesh="shoulderRollRight" material="black" class="visual" />
								<geom mesh="shoulderRollRight" class="visual" />
								<geom mesh="shoulderRollRight" class="visual" />
								<geom mesh="shoulderRollRight" class="visual" />
								<geom size="0.0354 0.021" pos="-0.035 0 0" quat="0.707105 0 0.707108 0" type="capsule" class="collision" />
								<body name="shoulderYawRight" pos="-0.0335 -0.034 -0.0585">
									<inertial pos="-0.00089274 -0.00096643 -0.0698052" quat="0.999767 0.0172729 -0.0100354 0.00814411" mass="0.6963" diaginertia="0.00304741 0.00298071 0.000413386" />
									<joint name="shoulderYaw_Right" pos="0 0 0" axis="0 0 1" range="-2.530 2.530" actuatorfrcrange="-65 65" />
									<geom mesh="shoulderYawRight" material="black" class="visual" />
									<geom mesh="shoulderYawRight" class="visual" />
									<geom size="0.0302 0.06" pos="0 0 -0.08" type="capsule" class="collision" />
									<body name="elbowRight" pos="0 0.0285 -0.20415">
										<inertial pos="-0.0121233 -0.0262957 -0.026584" quat="0.913189 -0.0537938 -0.213066 0.343213" mass="0.854" diaginertia="0.00116315 0.00108042 0.000405614" />
										<joint name="elbow_Right" pos="0 0 0" axis="0 1 0" range="-2.443 0.174" actuatorfrcrange="-30 30" />
										<geom mesh="elbowRight" class="visual" />
										<geom mesh="elbowRight" class="visual" />
										
									</body>
								</body>
							</body>
						</body>
					</body>
				</body>
			</body>
			<site name="imu" pos="0 0 0" />
		</body>
	</worldbody>
	<actuator>
		<motor name="hipPitch_Left" joint="hipPitch_Left" />
		<motor name="hipRoll_Left" joint="hipRoll_Left" />
		<motor name="hipYaw_Left" joint="hipYaw_Left" />
		<motor name="kneePitch_Left" joint="kneePitch_Left" />
		<motor name="anklePitch_Left" joint="anklePitch_Left" />
		<motor name="ankleRoll_Left" joint="ankleRoll_Left" />
		<motor name="hipPitch_Right" joint="hipPitch_Right" />
		<motor name="hipRoll_Right" joint="hipRoll_Right" />
		<motor name="hipYaw_Right" joint="hipYaw_Right" />
		<motor name="kneePitch_Right" joint="kneePitch_Right" />
		<motor name="anklePitch_Right" joint="anklePitch_Right" />
		<motor name="ankleRoll_Right" joint="ankleRoll_Right" />
		<motor name="waistRoll" joint="waistRoll" />
		<motor name="waistPitch" joint="waistPitch" />
		<motor name="waistYaw" joint="waistYaw" />
		<motor name="shoulderPitch_Left" joint="shoulderPitch_Left" />
		<motor name="shoulderRoll_Left" joint="shoulderRoll_Left" />
		<motor name="shoulderYaw_Left" joint="shoulderYaw_Left" />
		<motor name="elbow_Left" joint="elbow_Left" />
		<motor name="shoulderPitch_Right" joint="shoulderPitch_Right" />
		<motor name="shoulderRoll_Right" joint="shoulderRoll_Right" />
		<motor name="shoulderYaw_Right" joint="shoulderYaw_Right" />
		<motor name="elbow_Right" joint="elbow_Right" />
	</actuator>
	<sensor>
		<jointpos name="pos_hipPitch_Left" joint="hipPitch_Left" />
		<jointpos name="pos_hipRoll_Left" joint="hipRoll_Left" />
		<jointpos name="pos_hipYaw_Left" joint="hipYaw_Left" />
		<jointpos name="pos_kneePitch_Left" joint="kneePitch_Left" />
		<jointpos name="pos_anklePitch_Left" joint="anklePitch_Left" />
		<jointpos name="pos_ankleRoll_Left" joint="ankleRoll_Left" />
		<jointpos name="pos_hipPitch_Right" joint="hipPitch_Right" />
		<jointpos name="pos_hipRoll_Right" joint="hipRoll_Right" />
		<jointpos name="pos_hipYaw_Right" joint="hipYaw_Right" />
		<jointpos name="pos_kneePitch_Right" joint="kneePitch_Right" />
		<jointpos name="pos_anklePitch_Right" joint="anklePitch_Right" />
		<jointpos name="pos_ankleRoll_Right" joint="ankleRoll_Right" />
		<jointpos name="pos_waistRoll" joint="waistRoll" />
		<jointpos name="pos_waistPitch" joint="waistPitch" />
		<jointpos name="pos_waistYaw" joint="waistYaw" />
		<jointpos name="pos_shoulderPitch_Left" joint="shoulderPitch_Left" />
		<jointpos name="pos_shoulderRoll_Left" joint="shoulderRoll_Left" />
		<jointpos name="pos_shoulderYaw_Left" joint="shoulderYaw_Left" />
		<jointpos name="pos_elbow_Left" joint="elbow_Left" />
		<jointpos name="pos_shoulderPitch_Right" joint="shoulderPitch_Right" />
		<jointpos name="pos_shoulderRoll_Right" joint="shoulderRoll_Right" />
		<jointpos name="pos_shoulderYaw_Right" joint="shoulderYaw_Right" />
		<jointpos name="pos_elbow_Right" joint="elbow_Right" />
		<jointvel name="vel_hipPitch_Left" joint="hipPitch_Left" />
		<jointvel name="vel_hipRoll_Left" joint="hipRoll_Left" />
		<jointvel name="vel_hipYaw_Left" joint="hipYaw_Left" />
		<jointvel name="vel_kneePitch_Left" joint="kneePitch_Left" />
		<jointvel name="vel_anklePitch_Left" joint="anklePitch_Left" />
		<jointvel name="vel_ankleRoll_Left" joint="ankleRoll_Left" />
		<jointvel name="vel_hipPitch_Right" joint="hipPitch_Right" />
		<jointvel name="vel_hipRoll_Right" joint="hipRoll_Right" />
		<jointvel name="vel_hipYaw_Right" joint="hipYaw_Right" />
		<jointvel name="vel_kneePitch_Right" joint="kneePitch_Right" />
		<jointvel name="vel_anklePitch_Right" joint="anklePitch_Right" />
		<jointvel name="vel_ankleRoll_Right" joint="ankleRoll_Right" />
		<jointvel name="vel_waistRoll" joint="waistRoll" />
		<jointvel name="vel_waistPitch" joint="waistPitch" />
		<jointvel name="vel_waistYaw" joint="waistYaw" />
		<jointvel name="vel_shoulderPitch_Left" joint="shoulderPitch_Left" />
		<jointvel name="vel_shoulderRoll_Left" joint="shoulderRoll_Left" />
		<jointvel name="vel_shoulderYaw_Left" joint="shoulderYaw_Left" />
		<jointvel name="vel_elbow_Left" joint="elbow_Left" />
		<jointvel name="vel_shoulderPitch_Right" joint="shoulderPitch_Right" />
		<jointvel name="vel_shoulderRoll_Right" joint="shoulderRoll_Right" />
		<jointvel name="vel_shoulderYaw_Right" joint="shoulderYaw_Right" />
		<jointvel name="vel_elbow_Right" joint="elbow_Right" />
		<jointactuatorfrc name="force_hipPitch_Left" joint="hipPitch_Left" />
		<jointactuatorfrc name="force_hipRoll_Left" joint="hipRoll_Left" />
		<jointactuatorfrc name="force_hipYaw_Left" joint="hipYaw_Left" />
		<jointactuatorfrc name="force_kneePitch_Left" joint="kneePitch_Left" />
		<jointactuatorfrc name="force_anklePitch_Left" joint="anklePitch_Left" />
		<jointactuatorfrc name="force_ankleRoll_Left" joint="ankleRoll_Left" />
		<jointactuatorfrc name="force_hipPitch_Right" joint="hipPitch_Right" />
		<jointactuatorfrc name="force_hipRoll_Right" joint="hipRoll_Right" />
		<jointactuatorfrc name="force_hipYaw_Right" joint="hipYaw_Right" />
		<jointactuatorfrc name="force_kneePitch_Right" joint="kneePitch_Right" />
		<jointactuatorfrc name="force_anklePitch_Right" joint="anklePitch_Right" />
		<jointactuatorfrc name="force_ankleRoll_Right" joint="ankleRoll_Right" />
		<jointactuatorfrc name="force_waistRoll" joint="waistRoll" />
		<jointactuatorfrc name="force_waistPitch" joint="waistPitch" />
		<jointactuatorfrc name="force_waistYaw" joint="waistYaw" />
		<jointactuatorfrc name="force_shoulderPitch_Left" joint="shoulderPitch_Left" />
		<jointactuatorfrc name="force_shoulderRoll_Left" joint="shoulderRoll_Left" />
		<jointactuatorfrc name="force_shoulderYaw_Left" joint="shoulderYaw_Left" />
		<jointactuatorfrc name="force_elbow_Left" joint="elbow_Left" />
		<jointactuatorfrc name="force_shoulderPitch_Right" joint="shoulderPitch_Right" />
		<jointactuatorfrc name="force_shoulderRoll_Right" joint="shoulderRoll_Right" />
		<jointactuatorfrc name="force_shoulderYaw_Right" joint="shoulderYaw_Right" />
		<jointactuatorfrc name="force_elbow_Right" joint="elbow_Right" />
		<accelerometer name="BodyAcc" site="imu" />
		<gyro name="BodyGyro" site="imu" />
		<framepos name="BodyPos" objtype="site" objname="imu" />
		<framelinvel name="BodyVel" objtype="site" objname="imu" />
		<framequat name="BodyQuat" objtype="site" objname="imu" />
	</sensor>
</mujoco>
